<?xml version="1.0"?>
<robot name="evarobotmodel">
<!--BASE-->
	<link name="base_link">	
			<collision>
				<origin xyz="0 0 0" rpy="0 0 0"/>
				<geometry>
					<box size="0.4 0.3 0.3"/> 
				</geometry>
			</collision>
			<visual>
				<origin xyz="0.065 -0.11 -0.15" rpy="0 0 0" />  
				<geometry>
					<mesh filename="model://evarobotmodel_description/meshes/base.dae"/> 
				</geometry>
				<material name="Black" />
			</visual>
			<inertial>
				<origin xyz="0 0 0" rpy="0 0 0"/>
				<mass value="10.0"/>
				<inertia
					ixx="1.0" ixy="0" ixz="0"
					iyy="1.0" iyz="0"
					izz="1.0"/>
			</inertial>
		</link>
		<gazebo reference="base_link">
			<material>Gazebo/Black</material> 
		</gazebo>
		<link name="basecolor_link">		
			<collision>
				<origin xyz="0 0 0" rpy="0 0 0"/>
				<geometry>
					<box size="0.0001 0.0001 0.0001"/> 
				</geometry>
			</collision>			
			<visual>
				<origin xyz="0.065 -0.11 -0.15" rpy="0 0 0" /> 
				<geometry>
					<mesh filename="model://evarobotmodel_description/meshes/base_orange.dae"/>  
				</geometry>
				<material name="Orange" />
			</visual>
			<inertial>
				<origin xyz="0 0 0" rpy="0 0 0"/>
				<mass value="0.0001"/>
				<inertia
					ixx="1e-6" ixy="0.0" ixz="0.0"
					iyy="1e-6" iyz="0.0"
					izz="1e-6"/>
			</inertial>			
		</link>
		<gazebo reference="basecolor_link">
			<material>Gazebo/Orange</material> 
		</gazebo>				
		<joint name="basecolor_joint" type="fixed">
			<axis xyz="0 1 0" />
			<origin xyz="0 0 0" rpy="0 0 0"/>
			<parent link="base_link"/>
			<child link="basecolor_link"/>
		</joint>    
     <!--LEFT WHEEL-->
		<link name="left_wheel_link">
			<collision>
				<origin rpy="1.57075 0 0" xyz="0 0 0"/>
				<geometry>
					<cylinder length="0.035" radius="0.085"/>
				</geometry>
			</collision>
			<visual>
				<origin rpy="0 0 1.57079632679" xyz="0 0 0"/> 
				<geometry>
					 <mesh filename="model://evarobotmodel_description/meshes/rim.dae" scale="1 1 1"/> 
				</geometry>
				<material name="Grey"/>
			</visual>
			<inertial>
				<origin rpy="1.57075 0 0" xyz="0 0 0"/>
				<mass value="0.85"/>
				<inertia
					ixx="0.001" ixy="0" ixz="0"
					iyy="0.001" iyz="0"
					izz="0.001"/>
			</inertial>
		</link>
		<gazebo reference="left_wheel_link">
			<material>Gazebo/Grey</material>
			<mu1>1.0</mu1>
			<mu2>1.0</mu2>
			<kp>1000000.0</kp>
			<kd>100.0</kd>
			<minDepth>0.001</minDepth>
			<maxVel>1.0</maxVel>		
		</gazebo>
		<joint name="left_wheel_joint" type="continuous">
			<axis xyz="0 1 0"/>
			<parent link="base_link"/>
			<child link="left_wheel_link"/>
			<origin rpy="0.0 0.0 0.0" xyz="0.0 0.16 -0.119"/>
		</joint>
		<link name="left_wheeltire_link">
			<collision>
				<origin rpy="1.57075 0 0" xyz="0 0 0"/>
				<geometry>
					<cylinder length="0.001" radius="0.001"/>
				</geometry>
			</collision>
			<visual>
				<origin rpy="0 0 1.57079632679" xyz="0 0 0"/>
				<geometry>
					<mesh filename="model://evarobotmodel_description/meshes/tire.dae"/> 
				</geometry>
			</visual>
			<inertial>
				<origin xyz="0 0 0" rpy="0 0 0"/>
				<mass value="0.001"/>
				<inertia
					ixx="0.001" ixy="0" ixz="0"
					iyy="0.001" iyz="0"
					izz="0.001"/>
			</inertial>
		</link>
		<gazebo reference="left_wheeltire_link">
			<material>Gazebo/Black</material>
		</gazebo>	
		<joint name="left_wheeltire_joint" type="continuous">
			<axis xyz="0 1 0"/>
			<parent link="left_wheel_link"/>
			<child link="left_wheeltire_link"/>
			<origin rpy="0 0 0" xyz="0.0 0.0 0.0"/>
		</joint>     
<!--RIGHT WHEEL-->
		<link name="right_wheel_link">
			<collision>
				<origin rpy="1.57075 0 0" xyz="0 0 0"/>
				<geometry>
					<cylinder length="0.035" radius="0.085"/>
				</geometry>
			</collision>
			<visual>
				<origin rpy="0 0 1.57079632679" xyz="0 0 0"/> 
				<geometry>
					 <mesh filename="model://evarobotmodel_description/meshes/rim.dae" scale="1 1 1"/> 
				</geometry>
				<material name="Grey"/>
			</visual>
			<inertial>
				<origin rpy="1.57075 0 0" xyz="0 0 0"/>
				<mass value="0.85"/>
				<inertia
					ixx="0.001" ixy="0" ixz="0"
					iyy="0.001" iyz="0"
					izz="0.001"/>
			</inertial>
		</link>
		<gazebo reference="right_wheel_link">
			<material>Gazebo/Grey</material>
			<mu1>1.0</mu1>
			<mu2>1.0</mu2>
			<kp>1000000.0</kp>
			<kd>100.0</kd>
			<minDepth>0.001</minDepth>
			<maxVel>1.0</maxVel>		
		</gazebo>
		<joint name="right_wheel_joint" type="continuous">
			<axis xyz="0 1 0"/>
			<parent link="base_link"/>
			<child link="right_wheel_link"/>
			<origin rpy="0.0 0.0 0.0" xyz="0.0 -0.16 -0.119"/>
		</joint>
		<link name="right_wheeltire_link">
			<collision>
				<origin rpy="1.57075 0 0" xyz="0 0 0"/>
				<geometry>
					<cylinder length="0.001" radius="0.001"/>
				</geometry>
			</collision>
			<visual>
				<origin rpy="0 0 1.57079632679" xyz="0 0 0"/>
				<geometry>
					<mesh filename="model://evarobotmodel_description/meshes/tire.dae" scale="1 1 1"/> 
				</geometry>
				<material name="Black"/>
			</visual>
			<inertial>
				<origin xyz="0 0 0" rpy="0 0 0"/>
				<mass value="0.001"/>
				<inertia
					ixx="0.001" ixy="0" ixz="0"
					iyy="0.001" iyz="0"
					izz="0.001"/>
			</inertial>
		</link>
		<gazebo reference="right_wheeltire_link">
			<material>Gazebo/Black</material>
		</gazebo>	
		<joint name="right_wheeltire_joint" type="continuous">
			<axis xyz="0 1 0"/>
			<parent link="right_wheel_link"/>
			<child link="right_wheeltire_link"/>
			<origin rpy="0 0 0" xyz="0.0 0.0 0.0"/>
		</joint>     
		<!--FRONT CASTER-->
		<link name="front_caster_base_link">
			<collision>
				<origin rpy="0 0 0" xyz="0 0 0"/>
				<geometry>
					<box size="0.06 0.06 0.0135"/>				
				</geometry>
			</collision>
			<visual>
				<origin rpy="3.1415926535897931 0 0" xyz="-0.005 -0.01075 0.00675"/>
				<geometry>
					<mesh filename="model://evarobotmodel_description/meshes/caster_base.dae" scale="1 1 1"/> 
				</geometry>
				<material name="Grey"/>
			</visual>
			<inertial>
				<mass value="0.01" />
				<origin xyz="0 0 0" />
				<inertia ixx="1e-6" ixy="0.0" ixz="0.0"
								 iyy="1e-6" iyz="0.0" 
								 izz="1e-6" />
			</inertial>
		</link>
		<gazebo reference="front_caster_base_link">
			<material>Gazebo/Grey</material>
			<mu1>0.0</mu1>
			<mu2>0.0</mu2>
			<kp>1000000.0</kp>
			<kd>100.0</kd>
			<minDepth>0.001</minDepth>
			<maxVel>1.0</maxVel>			
		</gazebo>
		<joint name="front_caster_base_joint" type="fixed">
			<parent link="base_link"/>
			<child link="front_caster_base_link"/>
			<origin rpy="0.0 0.0 0.0" xyz="0.1604 0.0 -0.15675"/>
			<axis xyz="0 0 0"/>
		</joint>
		<link name="front_caster_rotate_link">
			<collision>
				<origin rpy="0 0 0" xyz="0 0 0"/>
				<geometry>
					<cylinder length="0.023" radius="0.0215"/>
				</geometry>
			</collision>
			<visual>
				<origin rpy="3.1415926535897931 0 1.57079632679" xyz="0 0 0.01"/>
				<geometry>
					<mesh filename="model://evarobotmodel_description/meshes/caster_rot.dae"/> 
				</geometry>
			</visual>
			<inertial>
				<mass value="0.01" />
				<origin xyz="0 0 0" />
				<inertia ixx="1e-6" ixy="0.0" ixz="0.0"
								 iyy="1e-6" iyz="0.0" 
								 izz="1e-6" />
			</inertial>
		</link>
		<gazebo reference="front_caster_rotate_link">
			<material>Gazebo/Grey</material>
			<mu1>0.0</mu1>
			<mu2>0.0</mu2>
			<kp>1000000.0</kp>
			<kd>100.0</kd>
			<minDepth>0.001</minDepth>
			<maxVel>1.0</maxVel>			
		</gazebo>
		<joint name="front_caster_base_rotate_joint" type="continuous">
			<parent link="front_caster_base_link"/>
			<child link="front_caster_rotate_link"/>
			<origin rpy="0 0 0" xyz="0.0 0.0 -0.0185"/>
			<axis xyz="0 0 1"/>
		</joint>						
		<link name="front_caster_wheel_link">
			<collision>
				<origin rpy="1.57079632679 0 0" xyz="0 0 0"/>
				<geometry>
					<sphere radius="0.0175"/>
				</geometry>
			</collision>
			<visual>
				<origin rpy="1.57079632679 0 0" xyz="0 0 0"/>
				<geometry>
					<sphere radius="0.0175"/>				
				</geometry>
			</visual>
			<inertial>
				<mass value="0.01" />
				<origin xyz="0 0 0" />
				<inertia ixx="1e-6" ixy="0.0" ixz="0.0"
								 iyy="1e-6" iyz="0.0" 
								 izz="1e-6" />
			</inertial>
		</link>
		<gazebo reference="front_caster_wheel_link">
			<material>Gazebo/Yellow</material>
			<mu1>0.0</mu1>
			<mu2>0.0</mu2>
			<kp>1000000.0</kp>
			<kd>100.0</kd>
			<minDepth>0.001</minDepth>
			<maxVel>1.0</maxVel>
		</gazebo>
		<joint name="front_caster_rotate_wheel_joint" type="continuous">
			<parent link="front_caster_rotate_link"/>
			<child link="front_caster_wheel_link"/>
			<origin rpy="0 0 0" xyz="-0.014632 0.0 -0.0115"/>
			<axis xyz="0.577350269 0.577350269 0.577350269"/>
		</joint>				
<!--REAR CASTER-->
		<link name="rear_caster_base_link">
			<collision>
				<origin rpy="0 0 0" xyz="0 0 0"/>
				<geometry>
					<box size="0.06 0.06 0.0135"/>				
				</geometry>
			</collision>
			<visual>
				<origin rpy="3.1415926535897931 0 0" xyz="-0.005 -0.01075 0.00675"/>
				<geometry>
					<mesh filename="model://evarobotmodel_description/meshes/caster_base.dae" scale="1 1 1"/> 
				</geometry>
				<material name="Grey"/>
			</visual>
			<inertial>
				<mass value="0.01" />
				<origin xyz="0 0 0" />
				<inertia ixx="1e-6" ixy="0.0" ixz="0.0"
								 iyy="1e-6" iyz="0.0" 
								 izz="1e-6" />
			</inertial>
		</link>
		<gazebo reference="rear_caster_base_link">
			<material>Gazebo/Grey</material>
			<mu1>0.0</mu1>
			<mu2>0.0</mu2>
			<kp>1000000.0</kp>
			<kd>100.0</kd>
			<minDepth>0.001</minDepth>
			<maxVel>1.0</maxVel>			
		</gazebo>
		<joint name="rear_caster_base_joint" type="fixed">
			<parent link="base_link"/>
			<child link="rear_caster_base_link"/>
			<origin rpy="0.0 0.0 0.0" xyz="-0.1604 0.0 -0.15675"/>
			<axis xyz="0 0 0"/>
		</joint>
		<link name="rear_caster_rotate_link">
			<collision>
				<origin rpy="0 0 0" xyz="0 0 0"/>
				<geometry>
					<cylinder length="0.023" radius="0.0215"/>
				</geometry>
			</collision>
			<visual>
				<origin rpy="3.1415926535897931 0 1.57079632679" xyz="0 0 0.01"/>
				<geometry>
					<mesh filename="model://evarobotmodel_description/meshes/caster_rot.dae" scale="1 1 1"/> 
				</geometry>
				<material name="Grey"/>
			</visual>
			<inertial>
				<mass value="0.01" />
				<origin xyz="0 0 0" />
				<inertia ixx="1e-6" ixy="0.0" ixz="0.0"
								 iyy="1e-6" iyz="0.0" 
								 izz="1e-6" />
			</inertial>
		</link>
		<gazebo reference="rear_caster_rotate_link">
			<material>Gazebo/Grey</material>
			<mu1>0.0</mu1>
			<mu2>0.0</mu2>
			<kp>1000000.0</kp>
			<kd>100.0</kd>
			<minDepth>0.001</minDepth>
			<maxVel>1.0</maxVel>			
		</gazebo>
		<joint name="rear_caster_base_rotate_joint" type="continuous">
			<parent link="rear_caster_base_link"/>
			<child link="rear_caster_rotate_link"/>
			<origin rpy="0 0 0" xyz="0.0 0.0 -0.0185"/>
			<axis xyz="0 0 1"/>
		</joint>						
		<link name="rear_caster_wheel_link">
			<collision>
				<origin rpy="1.57079632679 0 0" xyz="0 0 0"/>
				<geometry>
					<sphere radius="0.0175"/>
				</geometry>
			</collision>
			<visual>
				<origin rpy="1.57079632679 0 0" xyz="0 0 0"/>
				<geometry>
					<sphere radius="0.0175"/>				
				</geometry>
				<material name="Yellow"/>
			</visual>
			<inertial>
				<mass value="0.01" />
				<origin xyz="0 0 0" />
				<inertia ixx="1e-6" ixy="0.0" ixz="0.0"
								 iyy="1e-6" iyz="0.0" 
								 izz="1e-6" />
			</inertial>
		</link>
		<gazebo reference="rear_caster_wheel_link">
			<material>Gazebo/Yellow</material>
			<mu1>0.0</mu1>
			<mu2>0.0</mu2>
			<kp>1000000.0</kp>
			<kd>100.0</kd>
			<minDepth>0.001</minDepth>
			<maxVel>1.0</maxVel>
		</gazebo>
		<joint name="rear_caster_rotate_wheel_joint" type="continuous">
			<parent link="rear_caster_rotate_link"/>
			<child link="rear_caster_wheel_link"/>
			<origin rpy="0 0 0" xyz="-0.014632 0.0 -0.0115"/>
			<axis xyz="0.577350269 0.577350269 0.577350269"/>
		</joint>		
<!--KİNECT-->
		<link name="camera_link">
		  <visual>
			<origin xyz="0.0 0.0 0.004" rpy="0 0 0"/>
			<geometry>
			  <mesh filename="model://evarobotmodel_description/meshes/xtion_pro_camera.dae"/>
			</geometry>
		  </visual>
		  <collision>
			<origin xyz="0.0 0.0 0.0" rpy="0 0 0" />
			<geometry>
			<box size="0.0730 0.2760 0.0720"/>
		  </geometry>
		  </collision>
		  <inertial>
			<mass value="0.170" />
			<origin xyz="0 0 0" />
			<inertia ixx="0.001152600" ixy="0.0" ixz="0.0"
					 iyy="0.000148934" iyz="0.0"
					 izz="0.001154654" />
		  </inertial>
		</link>
		<joint name="camera_rgb_joint" type="fixed">
				<origin xyz="0.0 -0.02 0.0" rpy="0.0 0.0 0.0"/>
				<parent link="camera_link"/>
		  <child link="camera_rgb_frame" />
		</joint>
		<link name="camera_rgb_frame"/>
		<joint name="camera_rgb_optical_joint" type="fixed">
		  <origin xyz="0 0 0" rpy="-1.57079632679 0 -1.57079632679" />
		  <parent link="camera_rgb_frame" />
		  <child link="camera_rgb_optical_frame" />
		</joint>
		<link name="camera_rgb_optical_frame"/>
		<joint name="camera_joint" type="fixed">
				<origin xyz="0.17 0.0 0.1913" rpy="0.0 0.0 0.0"/>
		  <parent link="base_link"/>
		  <child link="camera_link"/>
		</joint>
		<joint name="camera_depth_joint" type="fixed">
		  <origin xyz="0 -0.045 0" rpy="0 0 0" />
		  <parent link="camera_link" />
		  <child link="camera_depth_frame" />
		</joint>
		<link name="camera_depth_frame"/>
		<joint name="camera_depth_optical_joint" type="fixed">
		  <origin xyz="0 0 0" rpy="-1.57079632679 0 -1.57079632679" />
		  <parent link="camera_depth_frame" />
		  <child link="camera_depth_optical_frame" />
		</joint>
		<link name="camera_depth_optical_frame"/>
		<!-- Asus mount -->
		<joint name="mount_asus_xtion_pro_joint" type="fixed">
				<origin xyz="0.1685 -0.0050 0.1563" rpy="1.57079632679 0 -1.57079632679"/>
		  <parent link="base_link"/>
		  <child link="mount_asus_xtion_pro_link"/>
		</joint>  
		<link name="mount_asus_xtion_pro_link">
		  <visual>
			<origin xyz="0 0 0" rpy="0 0 0"/>
			<geometry>
			  <mesh filename="model://evarobotmodel_description/meshes/asus_base.dae"/>
			</geometry>
			<material name="Black"/>
		  </visual>  
		  <collision>
			<origin xyz="0.0 0.0 0.0" rpy="0 0 0" />
			<geometry>
			<box size="0.2760 0.0330 0.0120"/>
		  </geometry>
		  </collision>
		  <inertial>
			<mass value="0.170" />
			<origin xyz="0 0 0" />
			<inertia ixx="0.001152600" ixy="0.0" ixz="0.0"
					 iyy="0.000148934" iyz="0.0"
					 izz="0.001154654" />
		  </inertial>
		</link>
		<gazebo reference="mount_asus_xtion_pro_link">
			<material>Gazebo/Black</material>
		</gazebo>
		<gazebo reference="camera_link">  
		  <sensor type="depth" name="camera">
			<always_on>true</always_on>
			<update_rate>20.0</update_rate>
			<camera>
			  <horizontal_fov>1.0471975512</horizontal_fov>
			  <image>
				<format>R8G8B8</format>
				<width>640</width>
				<height>480</height>
			  </image>
			  <clip>
				<near>0.05</near>
				<far>8.0</far>
			  </clip>
			</camera>
			<plugin name="kinect_camera_controller" filename="libgazebo_ros_openni_kinect.so">
			  <cameraName>camera</cameraName>
			  <alwaysOn>true</alwaysOn>
			  <updateRate>10</updateRate>
			  <imageTopicName>rgb/image_raw</imageTopicName>
			  <depthImageTopicName>depth/image_raw</depthImageTopicName>
			  <pointCloudTopicName>depth/points</pointCloudTopicName>
			  <cameraInfoTopicName>rgb/camera_info</cameraInfoTopicName>
			  <depthImageCameraInfoTopicName>depth/camera_info</depthImageCameraInfoTopicName>
			  <frameName>camera_depth_optical_frame</frameName>
			  <baseline>0.1</baseline>
			  <pointCloudCutoff>0.4</pointCloudCutoff>
	 		  <distortionK1>0.00000001</distortionK1>
			  <distortionK2>0.00000001</distortionK2>
			  <distortionK3>0.00000001</distortionK3>
			  <distortionT1>0.00000001</distortionT1>
			  <distortionT2>0.00000001</distortionT2>
			  <CxPrime>0</CxPrime>
			  <Cx>0</Cx>
			  <Cy>0</Cy>
			  <focalLength>0</focalLength>
			 <hackBaseline>0</hackBaseline>
			</plugin>
		  </sensor>
		</gazebo>
 <!--LİDAR-->
		<link name="lidar_link">
			<collision>
				<origin xyz="0 0 0" rpy="0 0 0"/>
				<geometry>
					<box size="0.1 0.1 0.1"/>
				</geometry>
			</collision>
			<visual>
				<origin xyz="-0.055 -0.11 -0.05" rpy="-1.57079632679 3.1415926535897931 0"/>
				<geometry>
					<mesh filename="model://evarobotmodel_description/meshes/rplidar.dae" scale="0.001 0.001 0.001" />
				</geometry>
				<material name="Black" />
			</visual>
			<inertial>
				<mass value="1e-5" />
				<origin xyz="0 0 0" rpy="0 0 0"/>
				<inertia ixx="1e-6" ixy="0" ixz="0" iyy="1e-6" iyz="0" izz="1e-6" />
			</inertial>
		</link>
		<joint name="lidar_joint" type="fixed">
			<axis xyz="0 1 0" />
			<origin xyz="-0.15 0.0 0.5415" rpy="0.0 0.0 3.14"/>
			<parent link="base_link"/>
			<child link="lidar_link"/>
		</joint>
		<gazebo reference="lidar_link">
			<material>Gazebo/Black</material>
			<sensor type="gpu_ray" name="head_hokuyo_sensor">
				<pose>0 0 0 0 0 0</pose>
				<visualize>false</visualize>
				<update_rate>40</update_rate>
				<ray>
					<scan>
						<horizontal>
							<samples>720</samples>
							<resolution>1</resolution>
							<min_angle>-3.1416</min_angle>
							<max_angle>3.1416</max_angle>
						</horizontal>
					</scan>
					<range>
						<min>0.5</min>
						<max>5.0</max>
						<resolution>0.1</resolution>
					</range>
					<noise>
						<type>gaussian</type>
					<!--	 Noise parameters based on published spec for Hokuyo laser
						achieving "+-30mm" accuracy at range < 10m.  A mean of 0.0m and
						stddev of 0.01m will put 99.7% of samples within 0.03m of the true
						reading.  -->
						<mean>0.0</mean>
						<stddev>0.01</stddev>
					</noise>
				</ray>
    			<plugin name="lidar_controller" filename="libgazebo_ros_gpu_laser.so">
					<topicName>lidar</topicName>
					<frameName>lidar_link</frameName>
				</plugin> 
			</sensor>
		</gazebo>    	
		<!--SONAR0-->
		<link name="sonar0_link">
			<inertial>
				<mass value="0.001" />
				<origin xyz="0 0 0" rpy="0 0 0" />
				<inertia ixx="1e-6" ixy="0" ixz="0" iyy="1e-6" iyz="0" izz="1e-6" />
			</inertial>				
			<collision>
				<origin xyz="0 0 0" rpy="0 0 0" />
				<geometry>
					<box size="0.01 0.01 0.01" />
				</geometry>
			</collision>
		</link>
		<joint name="sonar0_joint" type="fixed">
			<origin xyz="0.130 -0.147 0.08" rpy="0 0 -1.0471975512" />
			<axis xyz="1 0 0" />
			<parent link="base_link"/>
			<child link="sonar0_link"/>
		</joint>
		<!-- Sonar Plugin -->
		<gazebo reference="sonar0_link">
			<sensor type="ray" name="sonar0">
				<pose>0 0 0 0 0 0</pose>
				<ray>
					<scan>
						<horizontal>
							<samples>320</samples>
							<resolution>1</resolution>
							<min_angle>-0.479965544</min_angle>
							<max_angle>0.479965544</max_angle>
						</horizontal>
					</scan>
					<range>
						<min>0.02</min>
						<max>5.0</max>
						<resolution>0.01</resolution>
					</range>
				</ray>
				<plugin name="sonar0_plugin" filename="libim_gazebo_ros_sonar.so">
					<topicName>sonar0</topicName>
					<frameName>sonar0_link</frameName>
					<frameId>sonar0_link</frameId>
					<radiation>ultrasound</radiation>
					<fov>0.7</fov>
					<gaussianNoise>0</gaussianNoise>
				</plugin>
				<always_on>1</always_on>
				<update_rate>4</update_rate>
				<visualize>false</visualize>
			</sensor>
		</gazebo>		
		<!--SONAR1-->
		<link name="sonar1_link">
			<inertial>
				<mass value="0.001" />
				<origin xyz="0 0 0" rpy="0 0 0" />
				<inertia ixx="1e-6" ixy="0" ixz="0" iyy="1e-6" iyz="0" izz="1e-6" />
			</inertial>				
			<collision>
				<origin xyz="0 0 0" rpy="0 0 0" />
				<geometry>
					<box size="0.01 0.01 0.01" />
				</geometry>
			</collision>
		</link>
		<joint name="sonar1_joint" type="fixed">
			<origin xyz="0.213 0.0 0.08" rpy="0 0 0" />
			<axis xyz="1 0 0" />
			<parent link="base_link"/>
			<child link="sonar1_link"/>
		</joint>
		<!-- Sonar Plugin -->
		<gazebo reference="sonar1_link">
			<sensor type="ray" name="sonar1">
				<pose>0 0 0 0 0 0</pose>
				<ray>
					<scan>
						<horizontal>
							<samples>320</samples>
							<resolution>1</resolution>
							<min_angle>-0.479965544</min_angle>
							<max_angle>0.479965544</max_angle>
						</horizontal>
					</scan>
					<range>
						<min>0.02</min>
						<max>5.0</max>
						<resolution>0.01</resolution>
					</range>
				</ray>
				<plugin name="sonar1_plugin" filename="libim_gazebo_ros_sonar.so">
					<topicName>sonar1</topicName>
					<frameName>sonar1_link</frameName>
					<frameId>sonar1_link</frameId>
					<radiation>ultrasound</radiation>
					<fov>0.7</fov>
					<gaussianNoise>0</gaussianNoise>
				</plugin>
				<always_on>1</always_on>
				<update_rate>4</update_rate>
				<visualize>false</visualize>
			</sensor>
		</gazebo>				
		
		<!--SONAR2-->
		<link name="sonar2_link">
			<inertial>
				<mass value="0.001" />
				<origin xyz="0 0 0" rpy="0 0 0" />
				<inertia ixx="1e-6" ixy="0" ixz="0" iyy="1e-6" iyz="0" izz="1e-6" />
			</inertial>				
			<collision>
				<origin xyz="0 0 0" rpy="0 0 0" />
				<geometry>
					<box size="0.01 0.01 0.01" />
				</geometry>
			</collision>
		</link>
		<joint name="sonar2_joint" type="fixed">
			<origin xyz="0.130 0.147 0.08" rpy="0 0 1.0471975512" />
			<axis xyz="1 0 0" />
			<parent link="base_link"/>
			<child link="sonar2_link"/>
		</joint>
		<!-- Sonar Plugin -->
		<gazebo reference="sonar2_link">
			<sensor type="ray" name="sonar2">
				<pose>0 0 0 0 0 0</pose>
				<ray>
					<scan>
						<horizontal>
							<samples>320</samples>
							<resolution>1</resolution>
							<min_angle>-0.479965544</min_angle>
							<max_angle>0.479965544</max_angle>
						</horizontal>
					</scan>
					<range>
						<min>0.02</min>
						<max>5.0</max>
						<resolution>0.01</resolution>
					</range>
				</ray>
				<plugin name="sonar2_plugin" filename="libim_gazebo_ros_sonar.so">
					<topicName>sonar2</topicName>
					<frameName>sonar2_link</frameName>
					<frameId>sonar2_link</frameId>
					<radiation>ultrasound</radiation>
					<fov>0.7</fov>
					<gaussianNoise>0</gaussianNoise>
				</plugin>
				<always_on>1</always_on>
				<update_rate>4</update_rate>
				<visualize>false</visualize>
			</sensor>
		</gazebo>		
		<!--SONAR3-->
		<link name="sonar3_link">
			<inertial>
				<mass value="0.001" />
				<origin xyz="0 0 0" rpy="0 0 0" />
				<inertia ixx="1e-6" ixy="0" ixz="0" iyy="1e-6" iyz="0" izz="1e-6" />
			</inertial>				
			<collision>
				<origin xyz="0 0 0" rpy="0 0 0" />
				<geometry>
					<box size="0.01 0.01 0.01" />
				</geometry>
			</collision>
		</link>
		<joint name="sonar3_joint" type="fixed">
			<origin xyz="-0.045 0.168 0.08" rpy="0 0 1.57079632679" />
			<axis xyz="1 0 0" />
			<parent link="base_link"/>
			<child link="sonar3_link"/>
		</joint>
		<!-- Sonar Plugin -->
		<gazebo reference="sonar3_link">
			<sensor type="ray" name="sonar3">
				<pose>0 0 0 0 0 0</pose>
				<ray>
					<scan>
						<horizontal>
							<samples>320</samples>
							<resolution>1</resolution>
							<min_angle>-0.479965544</min_angle>
							<max_angle>0.479965544</max_angle>
						</horizontal>
					</scan>
					<range>
						<min>0.02</min>
						<max>5.0</max>
						<resolution>0.01</resolution>
					</range>
				</ray>
				<plugin name="sonar3_plugin" filename="libim_gazebo_ros_sonar.so">
					<topicName>sonar3</topicName>
					<frameName>sonar3_link</frameName>
					<frameId>sonar3_link</frameId>
					<radiation>ultrasound</radiation>
					<fov>0.7</fov>
					<gaussianNoise>0</gaussianNoise>
				</plugin>
				<always_on>1</always_on>
				<update_rate>4</update_rate>
				<visualize>false</visualize>
			</sensor>
		</gazebo>				
		<!--SONAR4-->
		<link name="sonar4_link">
			<inertial>
				<mass value="0.001" />
				<origin xyz="0 0 0" rpy="0 0 0" />
				<inertia ixx="1e-6" ixy="0" ixz="0" iyy="1e-6" iyz="0" izz="1e-6" />
			</inertial>				
			<collision>
				<origin xyz="0 0 0" rpy="0 0 0" />
				<geometry>
					<box size="0.01 0.01 0.01" />
				</geometry>
			</collision>
		</link>
		<joint name="sonar4_joint" type="fixed">
			<origin xyz="-0.191 0.084 0.08" rpy="0 0 2.61799387799" />
			<axis xyz="1 0 0" />
			<parent link="base_link"/>
			<child link="sonar4_link"/>
		</joint>
		<!-- Sonar Plugin -->
		<gazebo reference="sonar4_link">
			<sensor type="ray" name="sonar4">
				<pose>0 0 0 0 0 0</pose>
				<ray>
					<scan>
						<horizontal>
							<samples>320</samples>
							<resolution>1</resolution>
							<min_angle>-0.479965544</min_angle>
							<max_angle>0.479965544</max_angle>
						</horizontal>
					</scan>
					<range>
						<min>0.02</min>
						<max>5.0</max>
						<resolution>0.01</resolution>
					</range>
				</ray>
				<plugin name="sonar4_plugin" filename="libim_gazebo_ros_sonar.so">
					<topicName>sonar4</topicName>
					<frameName>sonar4_link</frameName>
					<frameId>sonar4_link</frameId>
					<radiation>ultrasound</radiation>
					<fov>0.7</fov>
					<gaussianNoise>0</gaussianNoise>
				</plugin>
				<always_on>1</always_on>
				<update_rate>4</update_rate>
				<visualize>false</visualize>
			</sensor>
		</gazebo>				
		
		<!--SONAR5-->
		<link name="sonar5_link">
			<inertial>
				<mass value="0.001" />
				<origin xyz="0 0 0" rpy="0 0 0" />
				<inertia ixx="1e-6" ixy="0" ixz="0" iyy="1e-6" iyz="0" izz="1e-6" />
			</inertial>				
			<collision>
				<origin xyz="0 0 0" rpy="0 0 0" />
				<geometry>
					<box size="0.01 0.01 0.01" />
				</geometry>
			</collision>
		</link>
		<joint name="sonar5_joint" type="fixed">
			<origin xyz="-0.191 -0.084 0.08" rpy="0 0 -2.61799387799" />
			<axis xyz="1 0 0" />
			<parent link="base_link"/>
			<child link="sonar5_link"/>
		</joint>
		<!-- Sonar Plugin -->
		<gazebo reference="sonar5_link">
			<sensor type="ray" name="sonar5">
				<pose>0 0 0 0 0 0</pose>
				<ray>
					<scan>
						<horizontal>
							<samples>320</samples>
							<resolution>1</resolution>
							<min_angle>-0.479965544</min_angle>
							<max_angle>0.479965544</max_angle>
						</horizontal>
					</scan>
					<range>
						<min>0.02</min>
						<max>5.0</max>
						<resolution>0.01</resolution>
					</range>
				</ray>
				<plugin name="sonar5_plugin" filename="libim_gazebo_ros_sonar.so">
					<topicName>sonar5</topicName>
					<frameName>sonar5_link</frameName>
					<frameId>sonar5_link</frameId>
					<radiation>ultrasound</radiation>
					<fov>0.7</fov>
					<gaussianNoise>0</gaussianNoise>
				</plugin>
				<always_on>1</always_on>
				<update_rate>4</update_rate>
				<visualize>false</visualize>
			</sensor>
		</gazebo>		
		<!--SONAR6-->
		<link name="sonar6_link">
			<inertial>
				<mass value="0.001" />
				<origin xyz="0 0 0" rpy="0 0 0" />
				<inertia ixx="1e-6" ixy="0" ixz="0" iyy="1e-6" iyz="0" izz="1e-6" />
			</inertial>				
			<collision>
				<origin xyz="0 0 0" rpy="0 0 0" />
				<geometry>
					<box size="0.01 0.01 0.01" />
				</geometry>
			</collision>
		</link>
		<joint name="sonar6_joint" type="fixed">
			<origin xyz="-0.045 -0.168 0.08" rpy="0 0 -1.57079632679" />
			<axis xyz="1 0 0" />
			<parent link="base_link"/>
			<child link="sonar6_link"/>
		</joint>
		<!-- Sonar Plugin -->
		<gazebo reference="sonar6_link">
			<sensor type="ray" name="sonar6">
				<pose>0 0 0 0 0 0</pose>
				<ray>
					<scan>
						<horizontal>
							<samples>320</samples>
							<resolution>1</resolution>
							<min_angle>-0.479965544</min_angle>
							<max_angle>0.479965544</max_angle>
						</horizontal>
					</scan>
					<range>
						<min>0.02</min>
						<max>5.0</max>
						<resolution>0.01</resolution>
					</range>
				</ray>
				<plugin name="sonar6_plugin" filename="libim_gazebo_ros_sonar.so">
					<topicName>sonar6</topicName>
					<frameName>sonar6_link</frameName>
					<frameId>sonar6_link</frameId>
					<radiation>ultrasound</radiation>
					<fov>0.7</fov>
					<gaussianNoise>0</gaussianNoise>
				</plugin>
				<always_on>1</always_on>
				<update_rate>4</update_rate>
				<visualize>false</visualize>
			</sensor>
		</gazebo>	
		<!--IR0-->
		<link name="ir0_link">
			<inertial>
				<mass value="0.001" />
				<origin xyz="0 0 0" rpy="0 0 0" />
				<inertia ixx="1e-6" ixy="0" ixz="0" iyy="1e-6" iyz="0" izz="1e-6" />
			</inertial>
			<collision>
				<origin xyz="0 0 0" rpy="0 0 0" />
				<geometry>
					<box size="0.01 0.01 0.01" />
				</geometry>
			</collision>
		</link>		
		<joint name="ir0_joint" type="fixed">
			<origin xyz="0.191 -0.084 -0.072" rpy="0 0 -0.52359877559" />
			<axis xyz="1 0 0"/>
			<parent link="base_link"/>
			<child link="ir0_link"/>
		</joint>
		<gazebo reference="ir0_link">
			<sensor type="ray" name="ir0">
				<pose>0 0 0 0 0 0</pose>
				<ray>
					<scan>
						<horizontal>
							<samples>320</samples>
							<resolution>1</resolution>
							<min_angle>-0.001</min_angle>
							<max_angle>0.001</max_angle>
						</horizontal>
					</scan>
					
					<range>
						<min>0.1</min>
						<max>0.8</max>
						<resolution>0.01</resolution>
					</range>
				</ray>
				<plugin name="ir0_plugin" filename="libim_gazebo_ros_sonar.so">
					<topicName>ir0</topicName>
					<frameName>ir0_link</frameName>
					<frameId>ir0_link</frameId>
					<radiation>infrared</radiation>
					<fov>0.01</fov>
					<gaussianNoise>0</gaussianNoise>
				</plugin>
				<always_on>1</always_on>
				<update_rate>4</update_rate>
				<visualize>false</visualize>
			</sensor>
		</gazebo>
		<--İR1-->
		<link name="ir1_link">
			<inertial>
				<mass value="0.001" />
				<origin xyz="0 0 0" rpy="0 0 0" />
				<inertia ixx="1e-6" ixy="0" ixz="0" iyy="1e-6" iyz="0" izz="1e-6" />
			</inertial>
			<collision>
				<origin xyz="0 0 0" rpy="0 0 0" />
				<geometry>
					<box size="0.01 0.01 0.01" />
				</geometry>
			</collision>
		</link>		
		<joint name="ir1_joint" type="fixed">
			<origin xyz="0.191 0.084 -0.072" rpy="0 0 0.52359877559" />
			<axis xyz="1 0 0"/>
			<parent link="base_link"/>
			<child link="ir1_link"/>
		</joint>
		<gazebo reference="ir1_link">
			<sensor type="ray" name="ir1">
				<pose>0 0 0 0 0 0</pose>
				<ray>
					<scan>
						<horizontal>
							<samples>320</samples>
							<resolution>1</resolution>
							<min_angle>-0.001</min_angle>
							<max_angle>0.001</max_angle>
						</horizontal>
					</scan>
					
					<range>
						<min>0.1</min>
						<max>0.8</max>
						<resolution>0.01</resolution>
					</range>
				</ray>
				<plugin name="ir1_plugin" filename="libim_gazebo_ros_sonar.so">
					<topicName>ir1</topicName>
					<frameName>ir1_link</frameName>
					<frameId>ir1_link</frameId>
					<radiation>infrared</radiation>
					<fov>0.01</fov>
					<gaussianNoise>0</gaussianNoise>
				</plugin>
				<always_on>1</always_on>
				<update_rate>4</update_rate>
				<visualize>false</visualize>
			</sensor>
		</gazebo>			
		<!--IR2-->
		<link name="ir2_link">
			<inertial>
				<mass value="0.001" />
				<origin xyz="0 0 0" rpy="0 0 0" />
				<inertia ixx="1e-6" ixy="0" ixz="0" iyy="1e-6" iyz="0" izz="1e-6" />
			</inertial>
			<collision>
				<origin xyz="0 0 0" rpy="0 0 0" />
				<geometry>
					<box size="0.01 0.01 0.01" />
				</geometry>
			</collision>
		</link>		
		<joint name="ir2_joint" type="fixed">
			<origin xyz="-0.13 0.147 -0.072" rpy="0 0 2.09439510239" />
			<axis xyz="1 0 0"/>
			<parent link="base_link"/>
			<child link="ir2_link"/>
		</joint>
		<gazebo reference="ir2_link">
			<sensor type="ray" name="ir2">
				<pose>0 0 0 0 0 0</pose>
				<ray>
					<scan>
						<horizontal>
							<samples>320</samples>
							<resolution>1</resolution>
							<min_angle>-0.001</min_angle>
							<max_angle>0.001</max_angle>
						</horizontal>
					</scan>
					
					<range>
						<min>0.1</min>
						<max>0.8</max>
						<resolution>0.01</resolution>
					</range>
				</ray>
				<plugin name="ir2_plugin" filename="libim_gazebo_ros_sonar.so">
					<topicName>ir2</topicName>
					<frameName>ir2_link</frameName>
					<frameId>ir2_link</frameId>
					<radiation>infrared</radiation>
					<fov>0.01</fov>
					<gaussianNoise>0</gaussianNoise>
				</plugin>
				<always_on>1</always_on>
				<update_rate>4</update_rate>
				<visualize>false</visualize>
			</sensor>
		</gazebo>		
		<!--IR3-->
		<link name="ir3_link">
			<inertial>
				<mass value="0.001" />
				<origin xyz="0 0 0" rpy="0 0 0" />
				<inertia ixx="1e-6" ixy="0" ixz="0" iyy="1e-6" iyz="0" izz="1e-6" />
			</inertial>
			<collision>
				<origin xyz="0 0 0" rpy="0 0 0" />
				<geometry>
					<box size="0.01 0.01 0.01" />
				</geometry>
			</collision>
		</link>		
		<joint name="ir3_joint" type="fixed">
			<origin xyz="-0.13 -0.147 -0.072" rpy="0 0 -2.09439510239" />
			<axis xyz="1 0 0"/>
			<parent link="base_link"/>
			<child link="ir3_link"/>
		</joint>
		<gazebo reference="ir3_link">
			<sensor type="ray" name="ir3">
				<pose>0 0 0 0 0 0</pose>
				<ray>
					<scan>
						<horizontal>
							<samples>320</samples>
							<resolution>1</resolution>
							<min_angle>-0.001</min_angle>
							<max_angle>0.001</max_angle>
						</horizontal>
					</scan>
					
					<range>
						<min>0.1</min>
						<max>0.8</max>
						<resolution>0.01</resolution>
					</range>
				</ray>
				<plugin name="ir3_plugin" filename="libim_gazebo_ros_sonar.so">
					<topicName>ir3</topicName>
					<frameName>ir3_link</frameName>
					<frameId>ir3_link</frameId>
					<radiation>infrared</radiation>
					<fov>0.01</fov>
					<gaussianNoise>0</gaussianNoise>
				</plugin>
				<always_on>1</always_on>
				<update_rate>4</update_rate>
				<visualize>false</visualize>
			</sensor>
		</gazebo>		
		<!--BUMPER0-->
		<link name="bumper0_link">
			<collision>
				<origin xyz="0 0 0" rpy="0 0 0"/>
				<geometry>
				<box size="0.015 0.015 0.02"/>
				</geometry>
			</collision>
			<inertial>
				<mass value="1e-5" />
				<origin xyz="0 0 0" rpy="0 0 0"/>
				<inertia ixx="1e-6" ixy="0" ixz="0" iyy="1e-6" iyz="0" izz="1e-6" />
			</inertial>
		</link>
		<!-- Bumper joint -->
		<joint name="bumper0_joint" type="fixed">
			<origin xyz="0.191 -0.084 -0.072" rpy="0 0 -0.52359877559" />
			<axis xyz="0 1 0" />
			<parent link="base_link"/>
			<child link="bumper0_link"/>
		</joint>
		<!-- Bumper plugin -->
		<gazebo reference="bumper0_link">
			<sensor name="bumper0" type="contact">
				<always_on>true</always_on>
				<update_rate>10</update_rate>
				<contact>
					<collision>bumper0_link_collision</collision>
				</contact>
				<plugin name="bumper0_plugin" filename="libim_gazebo_ros_bumper.so">
					<bumperTopicName>bumper0</bumperTopicName>
				<frameName>bumper0_link</frameName>
				</plugin>
			</sensor>
	    </gazebo>			
		<!--BUMPER1-->
		<link name="bumper1_link">
			<collision>
				<origin xyz="0 0 0" rpy="0 0 0"/>
				<geometry>
				<box size="0.015 0.015 0.02"/>
				</geometry>
			</collision>
			<inertial>
				<mass value="1e-5" />
				<origin xyz="0 0 0" rpy="0 0 0"/>
				<inertia ixx="1e-6" ixy="0" ixz="0" iyy="1e-6" iyz="0" izz="1e-6" />
			</inertial>
		</link>
		<!-- Bumper joint -->
		<joint name="bumper1_joint" type="fixed">
			<origin xyz="0.213 0 -0.072" rpy="0 0 0" />
			<axis xyz="0 1 0" />
			<parent link="base_link"/>
			<child link="bumper1_link"/>
		</joint>
		<!-- Bumper plugin -->
		<gazebo reference="bumper1_link">
			<sensor name="bumper1" type="contact">
				<always_on>true</always_on>
				<update_rate>10</update_rate>
				<contact>
					<collision>bumper1_link_collision</collision>
				</contact>
				<plugin name="bumper1_plugin" filename="libim_gazebo_ros_bumper.so">
					<bumperTopicName>bumper1</bumperTopicName>
				<frameName>bumper1_link</frameName>
				</plugin>
			</sensor>
	    </gazebo>			  
		<!--BUMPER2-->
		<link name="bumper2_link">
			<collision>
				<origin xyz="0 0 0" rpy="0 0 0"/>
				<geometry>
				<box size="0.015 0.015 0.02"/>
				</geometry>
			</collision>
			<inertial>
				<mass value="1e-5" />
				<origin xyz="0 0 0" rpy="0 0 0"/>
				<inertia ixx="1e-6" ixy="0" ixz="0" iyy="1e-6" iyz="0" izz="1e-6" />
			</inertial>
		</link>
		<!-- Bumper joint -->
		<joint name="bumper2_joint" type="fixed">
			<origin xyz="0.191 0.084 -0.072" rpy="0 0 0.52359877559" />
			<axis xyz="0 1 0" />
			<parent link="base_link"/>
			<child link="bumper2_link"/>
		</joint>
		<!-- Bumper plugin -->
		<gazebo reference="bumper2_link">
			<sensor name="bumper2" type="contact">
				<always_on>true</always_on>
				<update_rate>10</update_rate>
				<contact>
					<collision>bumper2_link_collision</collision>
				</contact>
				<plugin name="bumper2_plugin" filename="libim_gazebo_ros_bumper.so">
					<bumperTopicName>bumper2</bumperTopicName>
				<frameName>bumper2_link</frameName>
				</plugin>
			</sensor>
	    </gazebo>				
	    <!--AHRS-->
		<link name="imu_link">
			<inertial>
				<mass value="0.001"/>
				<origin rpy="0 0 0" xyz="0 0 0"/>
				<inertia ixx="0.0001" ixy="0" ixz="0" iyy="0.0001" iyz="0" izz="0.0001"/>
			</inertial>
			<visual>
				<origin rpy="0 0 0" xyz="0 0 0"/>
				<geometry>
					<box size="0.001 0.001 0.001"/>
				</geometry>
			</visual>
			<collision>
				<origin rpy="0 0 0" xyz="0 0 0"/>
				<geometry>
					<box size=".001 .001 .001"/>
				</geometry>
			</collision>
		</link>
		<joint name="imu_joint" type="fixed">
			<axis xyz="1 0 0"/>
			<origin xyz="0 0 0.19" rpy="3.1415926535897931 0 0" />
			<parent link="base_link"/>
			<child link="imu_link"/>
		</joint>
		<gazebo>
			<plugin name="imu_plugin" filename="libgazebo_ros_imu.so">
				<alwaysOn>true</alwaysOn>
				<frameName>imu_link</frameName>   
				<bodyName>imu_link</bodyName>
				<topicName>imu</topicName>
				<serviceName>imu_service</serviceName>
				<gaussianNoise>0.0</gaussianNoise>
				<updateRate>10</updateRate> 
			</plugin>
		</gazebo>
		 <gazebo>
			<plugin name="differential_drive_controller" filename="libgazebo_ros_diff_drive.so">
				<alwaysOn>true</alwaysOn>
				<updateRate>10.0</updateRate> 
				<robotBaseFrame>base_link</robotBaseFrame>
				<publishWheelTF>true</publishWheelTF>
				<publishWheelJointState>true</publishWheelJointState>
				<wheelAcceleration>1</wheelAcceleration>
				<leftJoint>right_wheel_joint</leftJoint>
				<rightJoint>left_wheel_joint</rightJoint>
				<wheelSeparation>0.33</wheelSeparation>
				<wheelDiameter>0.17</wheelDiameter>
				<wheelTorque>20</wheelTorque>
				<commandTopic>cmd_vel</commandTopic>
				<odometryTopic>odom</odometryTopic>
				<odometryFrame>odom_combined</odometryFrame>
				<robotNamespace>/</robotNamespace>
			</plugin>
		  </gazebo>			          
</robot>
